Workbook
Name B_eq: WACC!$E$7
Name D: WACC!$E$12
Name debt_ratio: WACC!$E$14
Name E: WACC!$E$11
Name equity_ratio: WACC!$E$13
Name leverage: WACC!$E$14
Name MRP: WACC!$E$9
Name Rd: WACC!$E$16
Name Re: WACC!$E$6
Name Rf: WACC!$E$8
Name scenario: 'DCF '!$C$16
Name tax_shield: WACC!$E$17

Sheet DCF 
F1: 2021 | G1: 2022 | H1: 2023 | I1: 2024 | J1: 2025 | K1: 2026 | L1: 2027 | M1: 2028 | N1: 2029 | O1: 2030
B2: NETFLIX DCF MODEL
A4: X | B4: General
B6: Company Ticker | C6: NFLX
B7: Date | C7: =TODAY() -> 46257
B8: End of Fiscal Year | C8: 46387
B9: Share Price | C9: 78
B10: Intrinsic Value | C10: =O121 -> 72.773146
B11: Delta | C11: =C10/C9-1 -> -0.067010945
A13: X | B13: Assumptions
B15: Triggers | L15: 1 - Bearish Case | P15: 2- Street Case | U15: 3- Bullish Case
B16: Scenario | C16: 2 | L16: Rev g FY2026 % street | N16: 0.8 | U16: Rev g FY2026 % street | W16: 1.25
B17: WACC | C17: =CHOOSE(scenario,N26,Q26,W26) -> 0.083152446 | L17: Rev g FY2030 % street | N17: 0.9 | U17: Rev g FY2030 % base | W17: 1.4
B18: TGR | C18: =CHOOSE(scenario,N27,Q27,W27) -> 0.025 | L18: EBITDA % FY2026 | N18: 0.635 | U18: EBITDA growth FY2026 | W18: 0.682
L19: EBITDA % FY2030 | N19: 0.71 | U19: EBITDA growth FY2030 | W19: 0.744
L20: EBIT % FY2026 | N20: =AVERAGE(F38:J38) -> 0.23082125 | U20: EBIT % FY2026 | W20: 0.325
L21: EBIT % FY2030 | N21: 0.32 | U21: EBIT % FY2030 | W21: 0.38
L22: CapEx % sales | N22: 0.02 | U22: CapEx % sales | W22: 0.015
L23: Content Spend % FY 2026 | N23: =AVERAGE($H$94:$J$94) -> -0.38907529 | P23: Content Spend % FY 2026 | R23: -0.375 | U23: Content Spend % FY 2026 | W23: =$N$23 -> -0.38907529
L24: Content Spend % FY 2030 | N24: -0.38 | P24: Content Spend % FY 2030 | R24: -0.35 | U24: Content Spend % FY 2030 | W24: -0.33
L26: WACC | N26: =Q26+0.5% -> 0.088152446 | P26: WACC | Q26: =WACC!E19 -> 0.083152446 | U26: WACC | W26: =Q26-0.5% -> 0.078152446
L27: TGR | N27: =Q27-0.5% -> 0.02 | P27: TGR | Q27: 0.025 | U27: TGR | W27: =Q27+0.5% -> 0.03
A29: X | B29: Financials
B31: Revenue | F31: =IS!F2 -> 29698 | G31: =IS!E2 -> 31616 | H31: =IS!D2 -> 33723 | I31: =IS!C2 -> 38877 | J31: =IS!B2 -> 45274 | K31: =J31*(1+K32) -> 52065.1 | L31: 57249 | M31: 63123 | N31: =M31+(M31*N32) -> 69750.915 | O31: =N31+(N31*O32) -> 76028.497
B32: % growth | G32: =G31/F31-1 -> 0.064583474 | H32: =H31/G31-1 -> 0.066643472 | I32: =I31/H31-1 -> 0.15283338 | J32: =J31/I31-1 -> 0.16454459 | K32: 0.15 | L32: =K32+($O$32-$K$32)/($O$1-$K$1) -> 0.135 | M32: =L32+($O$32-$K$32)/($O$1-$K$1) -> 0.12 | N32: =M32+($O$32-$K$32)/($O$1-$K$1) -> 0.105 | O32: 0.09
B34: EBITDA | F34: =IS!F48 -> 18633 | G34: =IS!E48 -> 19996 | H34: =IS!D48 -> 21508 | I34: =IS!C48 -> 25922 | J34: =IS!B48 -> 30175 | K34: =SUM(K37+K46) -> 34492.795 | L34: =SUM(L37+L46) -> 39237.137 | M34: =SUM(M37+M46) -> 44345.632 | N34: =SUM(N37+N46) -> 46180.23 | O34: =SUM(O37+O46) -> 50842.565
B35: % sales | F35: =F34/F$31 -> 0.62741599 | G35: =G34/G$31 -> 0.63246457 | H35: =H34/H$31 -> 0.6377843 | I35: =I34/I$31 -> 0.66676956 | J35: =J34/J$31 -> 0.66649733 | K35: =K34/K$31 -> 0.6624936 | L35: =L34/L$31 -> 0.6853768 | M35: =M34/M$31 -> 0.70252732 | ... O35: =O34/O$31 -> 0.66873037
B37: EBIT | F37: =IS!F51 -> 6195 | G37: =IS!E51 -> 5633 | H37: =IS!D51 -> 6954 | I37: =IS!C51 -> 10292 | J37: =IS!B51 -> 13419 | K37: ='Q2'!O14 -> 16298 | L37: 19480 | M37: 22892 | N37: =N31*N38 -> 22884.429 | O37: =O31*O38 -> 25546.412
B38: % sales | F38: =F37/F$31 -> 0.20859991 | G38: =G37/G$31 -> 0.17816928 | H38: =H37/H$31 -> 0.20620941 | I38: =I37/I$31 -> 0.26473236 | J38: =J37/J$31 -> 0.29639528 | K38: =K37/K$31 -> 0.31303119 | L38: =L37/L31 -> 0.34026795 | M38: =M37/M31 -> 0.36265703 | N38: =AVERAGE(J38:M38) -> 0.32808786 | O38: =AVERAGE(K38:N38) -> 0.33601101
B40: Taxes | F40: =IS!F26 -> 724 | G40: =IS!E26 -> 772 | H40: =IS!D26 -> 797 | I40: =IS!C26 -> 1254 | J40: =IS!B26 -> 1741 | K40: =K37*K41 -> 2021.3167 | L40: =L37*L41 -> 2443.8276 | M40: =M37*M41 -> 2818.781 | N40: =N37*N41 -> 2856.8603 | O40: =O37*O41 -> 3204.4881
B41: % tax rate | F41: =F40/F37 -> 0.11686844 | G41: =G40/G37 -> 0.13704953 | H41: =H40/H37 -> 0.1146103 | I41: =I40/I37 -> 0.12184221 | J41: =J40/J37 -> 0.12974141 | K41: =AVERAGE(F41:J41) -> 0.12402238 | L41: =AVERAGE(G41:K41) -> 0.12545316 | M41: =AVERAGE(H41:L41) -> 0.12313389 | N41: =AVERAGE(I41:M41) -> 0.12483861 | O41: =AVERAGE(J41:N41) -> 0.12543789
A44: X | B44: Cash Flow Items
B46: D&A | F46: =CF!F7 -> 12439 | G46: =CF!E7 -> 14363 | H46: =CF!D7 -> 14554 | I46: =CF!C7 -> 15630 | J46: =CF!B7 -> 16756 | K46: =J46+(J46*'Q2'!R39) -> 18194.795 | L46: =K46+(K46*'Q2'!R39) -> 19757.137 | M46: =L46+(L46*'Q2'!R39) -> 21453.632 | N46: =M46+(M46*'Q2'!R39) -> 23295.801 | O46: =N46+(N46*'Q2'!R39) -> 25296.153
B47: % sales | F47: =F46/F31 -> 0.41884975 | G47: =G46/G31 -> 0.45429529 | H47: =H46/H31 -> 0.43157489 | I47: =I46/I31 -> 0.40203719 | J47: =J46/J31 -> 0.37010205 | K47: =K46/K31 -> 0.34946241 | L47: =L46/L31 -> 0.34510885 | M47: =M46/M31 -> 0.33987028 | ... O47: =O46/O31 -> 0.33271936
B48: % CapEx
B50: CapEX | F50: =CF!F30 -> -552 | G50: =CF!E30 -> -408 | H50: =CF!D30 -> -349 | I50: =CF!C30 -> -440 | J50: =CF!B30 -> -688 | K50: =-(415+(415*1.2)) -> -913 | L50: =(L31*L51) -> -1144.98 | M50: =(M31*M51) -> -1262.46 | N50: =(N31*N51) -> -1046.2637 | O50: =(O31*O51) -> -912.34197
B51: % sales | F51: =(F50/F31) -> -0.01858711 | G51: =(G50/G31) -> -0.012904858 | H51: =(H50/H31) -> -0.01034902 | I51: =(I50/I31) -> -0.011317746 | J51: =(J50/J31) -> -0.01519636 | K51: =-(K50/K31) -> 0.017535739 | L51: -0.02 | M51: -0.02 | N51: -0.015 | O51: -0.012
B53: Changes in WC | G53: 1754 | H53: -278 | I53: 1288 | J53: =SUM((BS!B19-BS!B50)-(BS!C19-BS!C50)) -> -306 | K53: =K31*K54 -> 958.07449 | L53: =L31*L54 -> 522.81393 | M53: =M31*M54 -> 850.66188 | N53: =N31*N54 -> 597.26253 | O53: =O31*O54 -> 942.23643
B54: % sales | G54: =G53/G31 -> 0.055478239 | H54: =H53/H31 -> -0.0082436319 | I54: =I53/I31 -> 0.033130128 | J54: =J53/J31 -> -0.0067588461 | K54: =AVERAGE(G54:J54) -> 0.018401472 | L54: =AVERAGE(H54:K54) -> 0.0091322806 | M54: =AVERAGE(I54:L54) -> 0.013476259 | N54: =AVERAGE(J54:M54) -> 0.0085627914 | O54: =AVERAGE(K54:N54) -> 0.012393201
A58: X | B58: DCF Model
...

Sheet WACC
B2: WACC Calculation
A4: X | B4: Inputs | F4: WACC = [Re*(E/D+E)]+[Rd*(1-t )*(D/D+E)]
B6: Re | E6: =(Rf+B_eq*MRP) -> 0.085785952
B7: Beta Equity | E7: =D31 -> 0.86964019
B8: Risk Free Rate | E8: 0.047
B9: MRP | E9: 0.0446
B11: E | E11: 331410
B12: D | E12: 15363
B13: E/D+E | E13: =E/(D+E) -> 0.95569724
B14: D/D+E | E14: =D/(D+E) -> 0.044302757
B16: Rd | E16: =437762/14462000 -> 0.030269811
B17: 1-t | E17: =1-('DCF '!J41) -> 0.87025859
B19: WACC | E19: =Re*equity_ratio+Rd*tax_shield*debt_ratio -> 0.083152446
J20: =levB / (1+(1-taxR) * (D/E)
B22: Beta
B24: Company Name | D24: Lev Beta | E24: Market Cap | F24: Net Debt | G24: Tax Rate | H24: UnLev Beta
B25: Walt Disney | D25: 1.39 | E25: 187130 | F25: =38166+7257-5695 -> 39728 | G25: =-11.9% -> -0.119 | H25: =D25/(1+(1-G25)*(F25/E25)) -> 1.1231729
B26: Warner Bros | D26: 1.57 | E26: 71579 | F26: =32845-4570 -> 28275 | G26: 0.21 | H26: =D26/(1+(1-G26)*(F26/E26)) -> 1.1965877
B27: Paramount | D27: 1.47 | E27: 11583 | F27: =13225+433-3274 -> 10384 | G27: =AVERAGE(1%,1.2%,0.3%,2.7%) -> 0.013 | H27: =D27/(1+(1-G27)*(F27/E27)) -> 0.7799104
B28: ComCast | D28: 0.65 | E28: 95281 | F28: =92979+5958-9481 -> 89456 | G28: 0.237 | H28: =D28/(1+(1-G28)*(F28/E28)) -> 0.37870975
B30: Industry Average Ulbeta | D30: =AVERAGE(H25:H28) -> 0.86959518
B31: NFLX Lev Beta | D31: =D30*(1+(1-16.8%)*(E13/E12)) -> 0.86964019 | J31: unlevB * (1+(1-taxR) * (D/E))

Sheet IS
A1: Fiscal year is January-December. All values USD Millions. | B1: 2025 | C1: 2024 | D1: 2023 | E1: 2022 | F1: 2021
A2: Sales/Revenue | B2: 45274 | C2: 38877 | D2: 33723 | E2: 31616 | F2: 29698
A3: Sales Growth | B3: 0.1646 | C3: 0.1528 | D3: 0.0667 | E3: 0.0646 | F3: -
A4: Cost of Goods Sold (COGS) incl. D&A | B4: 23274 | C4: 21040 | D4: 19715 | E4: 19168 | F4: 17333
A5: COGS excluding D&A | B5: 6518 | C5: 5410 | D5: 5161 | E5: 4805 | F5: 4894
A6: Depreciation & Amortization Expense | B6: 16756 | C6: 15630 | D6: 14554 | E6: 14363 | F6: 12439
A7: COGS Growth | B7: 0.1062 | C7: 0.0672 | D7: 0.0285 | E7: 0.1059 | F7: -
A8: Gross Income | B8: 22000 | C8: 17837 | D8: 14008 | E8: 12447 | F8: 12365
A9: Gross Income Growth | B9: 0.2334 | C9: 0.2733 | D9: 0.1254 | E9: 0.0066 | F9: -
A10: Gross Profit Margin | B10: 0.4859 | C10: - | D10: - | E10: - | F10: -
A11: SG&A Expense | B11: 8581 | C11: 7545 | D11: 7054 | E11: 6814 | F11: 6171
A12: Research & Development | B12: 3391 | C12: 2925 | D12: 2676 | E12: 2711 | F12: 2274
A13: Other SG&A | B13: 5190 | C13: 4620 | D13: 4378 | E13: 4103 | F13: 3897
A14: SGA Growth | B14: 0.1373 | C14: 0.0696 | D14: 0.0351 | E14: 0.1043 | F14: -
A15: EBIT | B15: 13419 | C15: 10292 | D15: 6954 | E15: 5633 | F15: 6195
A16: Non Operating Income/Expense | B16: 80 | C16: 392 | D16: -49 | E16: 337 | F16: 411
A18: Interest Expense | B18: 777 | C18: 719 | D18: 700 | E18: 706 | F18: 766
A19: Interest Expense Growth | B19: 0.0804 | C19: 0.027 | D19: -0.009 | E19: -0.0776 | F19: -
A21: Gross Interest Expense | B21: 777 | C21: 719 | D21: 700 | E21: 706 | F21: 766
A22: Pretax Income | B22: 12723 | C22: 9966 | D22: 6205 | E22: 5264 | F22: 5840
A23: Pretax Income Growth | B23: 0.2766 | C23: 0.606 | D23: 0.1789 | E23: -0.0987 | F23: -
A25: Pretax Margin | B25: 0.281 | C25: - | D25: - | E25: - | F25: -
A26: Income Tax | B26: 1741 | C26: 1254 | D26: 797 | E26: 772 | F26: 724
A27: Income Tax - Current Domestic | B27: 1629 | C27: 1308 | D27: 1036 | E27: 230 | F27: 167
A28: Income Tax - Current Foreign | B28: 562 | C28: 537 | D28: 305 | E28: 677 | F28: 357
A29: Income Tax - Deferred Domestic | B29: -190 | C29: -562 | D29: -468 | E29: -83 | F29: 186
A31: Income Tax - Deferred Foreign | B31: -260 | C31: -29 | D31: -75 | E31: -51 | F31: 13
A33: Consolidated Net Income | B33: 10981 | C33: 8712 | D33: 5408 | E33: 4492 | F33: 5116
A34: Net Income | B34: 10981 | C34: 8712 | D34: 5408 | E34: 4492 | F34: 5116
A35: Net Income Growth | B35: 0.2605 | C35: 0.6109 | D35: 0.2039 | E35: -0.122 | F35: -
A37: Net Margin | B37: 0.2425 | C37: - | D37: - | E37: - | F37: -
A38: Net Income After Extraordinaries | B38: 10981 | C38: 8712 | D38: 5408 | E38: 4492 | F38: 5116
A39: Net Income Available to Common | B39: 10981 | C39: 8712 | D39: 5408 | E39: 4492 | F39: 5116
A40: EPS (Basic) | B40: 2.53 | C40: 1.98 | D40: 1.2 | E40: 1 | F40: 1.12
A41: EPS (Basic) Growth | B41: 0.2747 | C41: 0.6484 | D41: 0.2087 | E41: -0.114 | F41: -
A43: Basic Shares Outstanding | B43: 4250 | C43: 4295 | D43: 4416 | E43: 4447 | F43: 4432
A44: EPS (Diluted) | B44: 2.53 | C44: 1.98 | D44: 1.2 | E44: 1 | F44: 1.12
A45: EPS (Diluted) Growth | B45: 0.2747 | C45: 0.6484 | D45: 0.2087 | E45: -0.1141 | F45: -
A47: Diluted Shares Outstanding | B47: 4344 | C47: 4393 | D47: 4495 | E47: 4513 | F47: 4554
A48: EBITDA | B48: 30175 | C48: 25922 | D48: 21508 | E48: 19996 | F48: 18633
...

Sheet BS
A1: Assets
A3: Fiscal year is January-December. All values USD Millions. | B3: 2025 | C3: 2024 | D3: 2023 | E3: 2022 | F3: 2021
A4: Cash & Short Term Investments | B4: 9068 | C4: 9586 | D4: 7139 | E4: 6058 | F4: 6028
A5: Cash Only | B5: 8473 | C5: 7543 | D5: 6914 | E5: 5147 | F5: 6028
A6: Cash & Short Term Investments Growth | B6: -0.0541 | C6: 0.3427 | D6: 0.1784 | E6: 0.0051 | F6: -
A8: Cash & ST Investments / Total Assets | B8: 0.1631 | C8: 0.1744 | D8: 0.1435 | E8: 0.1247 | F8: 0.1352
A9: Total Accounts Receivable | B9: 2583 | C9: 1988 | D9: 1842 | E9: 989 | F9: 1718
A10: Accounts Receivables, Net | B10: 2031 | C10: 1335 | D10: 1287 | E10: 989 | F10: 804
A11: Accounts Receivables, Gross | B11: 2031 | C11: 1335 | D11: 1287 | E11: 989 | F11: 804
A12: Other Receivables | B12: 552 | C12: 653 | D12: 555 | E12: - | F12: 914
A13: Accounts Receivable Growth | B13: 0.2993 | C13: 0.0794 | D13: 0.8627 | E13: -0.4245 | F13: -
A15: Accounts Receivable Turnover | B15: 17.52 | C15: 19.55 | D15: 18.31 | E15: 31.97 | F15: 17.28
A16: Other Current Assets | B16: 1369 | C16: 1526 | D16: 937 | E16: 2219 | F16: 324
A17: Prepaid Expenses | B17: 498 | C17: 432 | D17: 409 | E17: 393 | F17: 324
A18: Miscellaneous Current Assets | B18: 871 | C18: 1094 | D18: 528 | E18: 1826 | F18: -
A19: Total Current Assets | B19: 13020 | C19: 13100 | D19: 9918 | E19: 9266 | F19: 8070
A20: Net Property, Plant & Equipment | B20: 4212 | C20: 3696 | D20: 3568 | E20: 3625 | F20: 3770
A21: Property, Plant & Equipment - Gross | B21: 5308 | C21: 4614 | D21: 4423 | E21: 4379 | F21: 4386
A22: Buildings | B22: 537 | C22: 476 | D22: 151 | E22: 52 | F22: 48
A23: Land & Improvements | B23: 156 | C23: 85 | D23: 88 | E23: 85 | F23: 82
A24: Machinery & Equipment | B24: 31 | C24: 15 | D24: 10 | E24: 27 | F24: 32
A25: Construction in Progress | B25: 285 | C25: 228 | D25: 406 | E25: 236 | F25: 282
A26: Computer Software and Equipment | B26: 572 | C26: 446 | D26: 414 | E26: 443 | F26: 380
A27: Transportation Equipment | B27: 99 | C27: 99 | D27: 99 | E27: 116 | F27: 111
A28: Other Property, Plant & Equipment | B28: 1421 | C28: 1162 | D28: 1177 | E28: 1194 | F28: 1003
A29: Accumulated Depreciation | B29: 1097 | C29: 918 | D29: 855 | E29: 754 | F29: 616
A30: Total Investments and Advances | B30: 89 | C30: 407 | D30: 5 | E30: 20 | F30: 24
... A35: Total Assets | B35: 55597 | C35: 54968 | D35: 49768 | E35: 48595 | F35: 44585
A36: Assets - Total - Growth | B36: 0.0114 | C36: 0.1045 | D36: 0.0241 | E36: 0.0899 | F36: -
A37: Asset Turnover | B37: 0.82 | C37: - | D37: - | E37: - | F37: -
A38: Return On Average Assets | B38: 0.1986 | C38: - | D38: - | E38: - | F38: -
A40: Liabilities & Shareholders' Equity
A42: All values USD Millions. | B42: 2025 | C42: 2024 | D42: 2023 | E42: 2022 | F42: 2021
A43: ST Debt & Current Portion LT Debt | B43: 1459 | C43: 2213 | D43: 783 | E43: 356 | F43: 1015
A44: Short Term Debt | B44: 1459 | C44: 2213 | D44: 783 | E44: 356 | F44: 1015
A45: Accounts Payable | B45: 901 | C45: 900 | D45: 747 | E45: 672 | F45: 837
A46: Accounts Payable Growth | B46: 0.0008 | C46: 0.204 | D46: 0.113 | E46: -0.1982 | F46: -
A48: Other Current Liabilities | B48: 8621 | C48: 7643 | D48: 7330 | E48: 6903 | F48: 6636
A49: Miscellaneous Current Liabilities | B49: 8621 | C49: 7643 | D49: 7330 | E49: 6903 | F49: 6636
A50: Total Current Liabilities | B50: 10981 | C50: 10755 | D50: 8861 | E50: 7931 | F50: 8489
...

Sheet CF
A1: Operating Activities
A3: Fiscal year is January-December. All values USD Millions. | B3: 2025 | C3: 2024 | D3: 2023 | E3: 2022 | F3: 2021
A4: Net Income before Extraordinaries | B4: 10981 | C4: 8712 | D4: 5408 | E4: 4492 | F4: 5116
A5: Net Income Growth | B5: 0.2605 | C5: 0.6109 | D5: 0.2039 | E5: -0.122 | F5: -
A7: Depreciation, Depletion & Amortization | B7: 16756 | C7: 15630 | D7: 14554 | E7: 14363 | F7: 12439
A8: Deferred Taxes & Investment Tax Credit | B8: -442 | C8: -591 | D8: -459 | E8: -167 | F8: 200
A10: Deferred Taxes | B10: -442 | C10: -591 | D10: -459 | E10: -167 | F10: 200
A12: Other Funds | B12: -16689 | C12: -16357 | D12: -12113 | E12: -15904 | F12: -17120
A14: Funds from Operations | B14: 10605 | C14: 7394 | D14: 7390 | E14: 2784 | F14: 635
A15: Changes in Working Capital | B15: -456 | C15: -33 | D15: -116 | E15: -758 | F15: -242
A17: Accounts Payable | B17: -8 | C17: 121 | D17: 94 | E17: -159 | F17: 145
A19: Other Accruals | B19: 881 | C19: 192 | D19: 104 | E19: -56 | F19: 180
A21: Other Assets/Liabilities | B21: -1329 | C21: -346 | D21: -313 | E21: -544 | F21: -567
A23: Net Operating Cash Flow | B23: 10149 | C23: 7361 | D23: 7274 | E23: 2026 | F23: 393
A24: Net Operating Cash Flow Growth | B24: 0.3787 | C24: 0.012 | D24: 2.59 | E24: 4.161 | F24: -
A25: Net Operating Cash Flow / Sales | B25: 0.2242 | C25: 0.1894 | D25: 0.2157 | E25: 0.0641 | F25: 0.0132
A27: Investing Activities
A29: All values USD Millions. | B29: 2025 | C29: 2024 | D29: 2023 | E29: 2022 | F29: 2021
A30: Capital Expenditures | B30: -688 | C30: -440 | D30: -349 | E30: -408 | F30: -552
A32: Capital Expenditures (Fixed Assets) | B32: -688 | C32: -440 | D32: -349 | E32: -408 | F32: -525
A34: Capital Expenditures (Other Assets) | B34: - | C34: - | D34: - | E34: - | F34: -27
A36: Capital Expenditures Growth | B36: -0.5658 | C36: -0.261 | D36: 0.1451 | E36: 0.2607 | F36: -
A38: Capital Expenditures / Sales | B38: -0.0152 | C38: -0.0113 | D38: -0.0103 | E38: -0.0129 | F38: -0.0186
A40: Purchase/Sale of Investments | B40: 1747 | C40: -1742 | D40: 890 | E40: -911 | F40: -
A42: Purchase of Investments | B42: -170 | C42: -1742 | D42: -505 | E42: -911 | F42: -
A44: Sale/Maturity of Investments | B44: 1917 | C44: - | D44: 1395 | E44: - | F44: -
A45: Other Uses | B45: -17 | C45: - | D45: - | E45: -757 | F45: -788
A47: Net Investing Cash Flow | B47: 1042 | C47: -2182 | D47: 542 | E47: -2076 | F47: -1340
A49: Net Investing Cash Flow Growth | B49: 1.4774 | C49: -5.0273 | D49: 1.2609 | E49: -0.5497 | F49: -
A51: Net Investing Cash Flow / Sales | B51: 0.023 | C51: -0.0561 | D51: 0.0161 | E51: -0.0657 | F51: -0.0451
A54: Financing Activities
A56: All values USD Millions. | B56: 2025 | C56: 2024 | D56: 2023 | E56: 2022 | F56: 2021 | G56: 5-year trend
A57: Change in Capital Stock | B57: -8460 | C57: -5431 | D57: -5875 | E57: 36 | F57: -426
A59: Repurchase of Common & Preferred Stk. | B59: -9127 | C59: -6264 | D59: -6045 | E59: - | F59: -600
A61: Sale of Common & Preferred Stock | B61: 667 | C61: 833 | D61: 170 | E61: 36 | F61: 174
A62: Proceeds from Stock Options | B62: 667 | C62: 833 | D62: 170 | E62: 36 | F62: 174
A63: Issuance/Reduction of Debt, Net | B63: -1833 | C63: 1394 | D63: - | E63: -700 | F63: -500
A65: Change in Long-Term Debt | B65: -1833 | C65: 1394 | D65: - | E65: -700 | F65: -500
A67: Issuance of Long-Term Debt | B67: - | C67: 1794 | D67: - | E67: - | F67: -
A68: Reduction in Long-Term Debt | B68: -1833 | C68: -400 | D68: - | E68: -700 | F68: -500
...

Sheet Q2
A1: Netflix, Inc.
A2: Consolidated Statements of Operations
A3: (unaudited)
A4: (in thousands, except per share data)
E5: Three Months Ended | I5: Twelve Months Ended | J5: Three Months Ended | L5: Six Months Ended
E6: March 31, | F6: June 30, | G6: September 30, | H6: December 31, | I6: December 31, | J6: March 31, | K6: June 30, | L6: June 30,
E7: 2025 | F7: 2025 | G7: 2025 | H7: 2025 | I7: 2025 | J7: 2026 | K7: 2026 | L7: 2026
A9: Revenues | E9: $ 10,542,801 | F9: $ 11,079,166 | G9: $ 11,510,307 | H9: $ 12,050,762 | I9: $ 45,183,036 | J9: $ 12,249,757 | K9: $ 12,559,938 | L9: $ 24,809,695 | N9: =O9*2 -> 49619390 | O9: 24809695
B10: Cost of revenues | E10: 5263147 | F10: 5325311 | G10: 6164250 | H10: 6522621 | I10: 23275329 | J10: 5888238 | K10: 6036965 | L10: 11925203
B11: Sales and marketing | E11: 688370 | F11: 713265 | G11: 786295 | H11: 1113376 | I11: 3301306 | J11: 842217 | K11: 823838 | L11: 1666055
B12: Technology and development | E12: 822823 | F12: 824683 | G12: 853584 | H12: 890300 | I12: 3391390 | J12: 959696 | K12: 1007675 | L12: 1967371
B13: General and administrative | E13: 421462 | F13: 441213 | G13: 457931 | H13: 567802 | I13: 1888408 | J13: 602609 | K13: 498850 | L13: 1101459
A14: Operating income | E14: 3346999 | F14: 3774694 | G14: 3248247 | H14: 2956663 | I14: 13326603 | J14: 3956997 | K14: 4192610 | L14: 8149607 | N14: 8149 | O14: =N14/50% -> 16298
A15: Other income (expense):
B16: Interest expense | E16: -184172 | F16: -182649 | G16: -175294 | H16: -234395 | I16: -776510 | J16: -262077 | K16: -175685 | L16: -437762 | M16: =437762/14462000 -> 0.030269811
B17: Interest and other income (expense) | E17: 50899 | F17: 39630 | G17: 36457 | H17: 45473 | I17: 172459 | J17: 2852166 | K17: 51661 | L17: 2903827 | N17: 8149607
A18: Income before income taxes | E18: 3213726 | F18: 3631675 | G18: 3109410 | H18: 2767741 | I18: 12722552 | J18: 6547086 | K18: 4068586 | L18: 10615672 | N18: 1931467
A19: Provision for income taxes | E19: -323375 | F19: -506262 | G19: -562494 | H19: -349220 | I19: -1741351 | J19: -1264295 | K19: -667172 | L19: -1931467
A20: Net income | E20: $ 2,890,351 | F20: $ 3,125,413 | G20: $ 2,546,916 | H20: $ 2,418,521 | I20: $ 10,981,201 | J20: $ 5,282,791 | K20: $ 3,401,414 | L20: $ 8,684,205
A21: Earnings per share*:
B22: Basic | E22: $ 0.68 | F22: $ 0.74 | G22: $ 0.60 | H22: $ 0.57 | I22: $ 2.58 | J22: $ 1.25 | K22: $ 0.81 | L22: $ 2.06
B23: Diluted | E23: $ 0.66 | F23: $ 0.72 | G23: $ 0.59 | H23: $ 0.56 | I23: $ 2.53 | J23: $ 1.23 | K23: $ 0.80 | L23: $ 2.03
A24: Weighted-average shares of common stock outstanding*:
B25: Basic | E25: 4272695 | F25: 4252112 | G25: 4244553 | H25: 4229221 | I25: 4249512 | J25: 4222787 | K25: 4189303 | L25: 4205952 | N25: Sh. Out. 2025 | O25: 4250
B26: Diluted | E26: 4369623 | F26: 4348825 | G26: 4340392 | H26: 4317144 | I26: 4343863 | J26: 4298437 | K26: 4261300 | L26: 4279776
A32: Net income | G32: 2890351 | H32: 3125413 | I32: 2546916 | J32: 2418521 | K32: 10981201 | L32: 5282791 | M32: 3401414 | N32: 8684205
A33: Adjustments to reconcile net income to net cash
B34: provided by operating activities:
C35: Additions to content assets | G35: -3549657 | H35: -3835813 | I35: -4653935 | J35: -5057212 | K35: -17096617 | L35: -4846917 | M35: -4927523 | N35: -9774440
C36: Change in content liabilities | G36: -411253 | H36: -214052 | I36: 24262 | J36: -9795 | K36: -610838 | L36: 45216 | M36: -181794 | N36: -136578 | P36: 2025 | Q36: h1 | R36: h2 | S36: increase? | U36: 2026 projected | V36: h1 | W36: h2 | X36: new tot
C37: Amortization of content assets | G37: 3823112 | H37: 3832074 | I37: 4002744 | J37: 4764236 | K37: 16422166 | L37: 4217900 | M37: 4311309 | N37: 8529209 | P37: =SUM(K37:K38) -> 16755555 | Q37: =SUM(G37:H38) -> 7815266 | R37: =SUM(I37:J38) -> 8940289 | S37: =R37-Q37 -> 1125023 | V37: =SUM(N37:N38) -> 8728314 | W37: =V37*(1+10%) -> 9601145.4 | X37: =SUM(V37:W37) -> 18329459
C38: Depreciation and amortization of property, equipment and intangibles | G38: 80067 | H38: 80013 | I38: 87326 | J38: 85983 | K38: 333389 | L38: 98575 | M38: 100530 | N38: 199105 | S38: =S37/Q37 -> 0.14395198
C39: Stock-based compensation expense | G39: 71977 | H39: 80862 | I39: 80986 | J39: 134624 | K39: 368449 | L39: 140405 | M39: 131312 | N39: 271717 | P39: increase 25/26 | Q39: =SUM(X37-P37) -> 1573904.4 | R39: =Q39/X37 -> 0.085867475
C40: Foreign currency remeasurement loss (gain) on debt | G40: 28547 | H40: 55238 | I40: -1707 | J40: -9730 | K40: 72348 | L40: -10110 | M40: -8813 | N40: -18923
C41: Other non-cash items | G41: 114730 | H41: 120139 | I41: 142293 | J41: 200289 | K41: 577451 | L41: 198227 | M41: 141356 | N41: 339583
C42: Deferred income taxes | G42: -163928 | H42: -135755 | I42: 20539 | J42: -162912 | K42: -442056 | L42: 58819 | M42: 81260 | N42: 140079
C43: Changes in operating assets and liabilities:
D44: Other current assets | G44: -131367 | H44: -176683 | I44: -169597 | J44: -313014 | K44: -790661 | L44: -704640 | M44: 111713 | N44: -592927
D45: Accounts payable | G45: -276426 | H45: 11046 | I45: 139451 | J45: 117890 | K45: -8039 | L45: 154 | M45: -157397 | N45: -157243
D46: Accrued expenses and other liabilities | G46: 306413 | H46: -267235 | I46: 707151 | J46: 134889 | K46: 881218 | L46: 1295904 | M46: -1249793 | N46: 46111
...
